Workbook

Sheet Project Plan
A1: sss — SAP S/4HANA Pre-Sales Plan (Greenfield)
A2: Phase Legend | D2: Discover | G2: Prepare | K2: Explore | Q2: Realize - Develop | AC2: Realize - UAT | AI2: Deploy | AK2: Run
D3: 1 | E3: 2 | F3: 3 | G3: 4 | H3: 5 | I3: 6 | J3: 7 | K3: 8 | L3: 9 | M3: 10 | N3: 11 | O3: 12 | P3: 13 | Q3: 14 | R3: 15 | S3: 16 | T3: 17 | U3: 18 | V3: 19 | W3: 20 | X3: 21 | Y3: 22 | Z3: 23 | AA3: 24 | AB3: 25 | AC3: 26 | AD3: 27 | AE3: 28 | AF3: 29 | AG3: 30 | AH3: 31 | AI3: 32 | AJ3: 33 | AK3: 34 | AL3: 35 | AM3: 36 | AN3: 37
A4: Calendar Week | D4: 22 Mar | E4: 29 Mar | F4: 5 Apr | G4: 12 Apr | H4: 19 Apr | I4: 26 Apr | J4: 3 May | K4: 10 May | L4: 17 May | M4: 24 May | N4: 31 May | O4: 7 Jun | P4: 14 Jun | Q4: 21 Jun | R4: 28 Jun | S4: 5 Jul | T4: 12 Jul | U4: 19 Jul | V4: 26 Jul | W4: 2 Aug | X4: 9 Aug | Y4: 16 Aug | Z4: 23 Aug | AA4: 30 Aug | AB4: 6 Sep | AC4: 13 Sep | AD4: 20 Sep | AE4: 27 Sep | AF4: 4 Oct | AG4: 11 Oct | AH4: 18 Oct | AI4: 25 Oct | AJ4: 1 Nov | AK4: 8 Nov | AL4: 15 Nov | AM4: 22 Nov | AN4: 29 Nov
A5: Phase | B5: Activity | C5: Responsible | D5: W1 | E5: W2 | F5: W3 | G5: W4 | H5: W5 | I5: W6 | J5: W7 | K5: W8 | L5: W9 | M5: W10 | N5: W11 | O5: W12 | P5: W13 | Q5: W14 | R5: W15 | S5: W16 | T5: W17 | U5: W18 | V5: W19 | W5: W20 | X5: W21 | Y5: W22 | Z5: W23 | AA5: W24 | AB5: W25 | AC5: W26 | AD5: W27 | AE5: W28 | AF5: W29 | AG5: W30 | AH5: W31 | AI5: W32 | AJ5: W33 | AK5: W34 | AL5: W35 | AM5: W36 | AN5: W37
A6: Discover | B6: Stakeholder Alignment & Vision Workshop | C6: Project Team
B7: Current State Assessment | C7: Project Team
B8: S/4HANA Business Case Development | C8: Project Team
B9: Solution Scope Definition | C9: Project Team
B10: High-Level Architecture Blueprint | C10: Project Team
B11: Executive Sponsorship Alignment | C11: Project Team
B12: Pre-Sales Presentation & Sign-Off | C12: Project Team
A13: Prepare | B13: Project Charter & Governance Setup | C13: Project Team
B14: SAP Activate Methodology Training | C14: Project Team
B15: System Landscape Design | C15: Project Team
B16: Project Standards & Templates | C16: Project Team
B17: Risk Register Initialisation | C17: Project Team
B18: Vendor & Partner Onboarding | C18: Project Team
B19: Infrastructure Procurement Plan | C19: Project Team
A20: Explore | B20: Fit-to-Standard Workshops (Finance) | C20: Project Team
B21: Fit-to-Standard Workshops (SCM/Logistics) | C21: Project Team
B22: Fit-to-Standard Workshops (HR/Payroll) | C22: Project Team
B23: Delta Design Decisions Log | C23: Project Team
B24: Integration Architecture Design | C24: Project Team
B25: Data Migration Strategy | C25: Project Team
B26: Master Data Governance Framework | C26: Project Team
A27: Realize - Develop | B27: System Configuration – Core Finance | C27: Project Team
B28: System Configuration – Procurement & Inventory | C28: Project Team
B29: Custom Development (RICEFW) | C29: Project Team
B30: Integration Development (CPI/BTP) | C30: Project Team
B31: Unit Testing & Code Reviews | C31: Project Team
B32: Master Data Load (Test Cycles) | C32: Project Team
B33: Security & Authorisation Design | C33: Project Team
A34: Realize - UAT | B34: User Acceptance Testing – Wave 1 | C34: Project Team
B35: User Acceptance Testing – Wave 2 | C35: Project Team
B36: Defect Management & Resolution | C36: Project Team
B37: Cutover Strategy & Runbook | C37: Project Team
B38: End-User Training Delivery | C38: Project Team
B39: Performance & Volume Testing | C39: Project Team
B40: Dress Rehearsal Go-Live Simulation | C40: Project Team
...

Sheet Resource Pivot
A1: sss — Resource Effort Pivot by Year
A2: Transition: Greenfield | Total Weeks: 37 | Model: gemini-1.5-flash
A3: No | B3: Role | C3: Description | D3: Location | E3: Level | F3: 2026 | G3: Total
A5: 1 | B5: Solution Architect | C5: Functional | D5: Onsite | E5: Sol. Architect | F5: =SUM('Project Plan'!E58:AO58) -> 0 | G5: =SUM(F5:F5) -> 0
A6: 2 | B6: SAP Functional Consultant | C6: Functional | D6: Onsite | E6: Sr | F6: =SUM('Project Plan'!E59:AO59) -> 0 | G6: =SUM(F6:F6) -> 0
A7: 3 | B7: SAP Functional Consultant | C7: Functional | D7: Offshore | E7: Sr | F7: =SUM('Project Plan'!E60:AO60) -> 0 | G7: =SUM(F7:F7) -> 0
A8: 4 | B8: SAP Functional Consultant | C8: Functional | D8: Offshore | E8: Jr | F8: =SUM('Project Plan'!E61:AO61) -> 0 | G8: =SUM(F8:F8) -> 0
A9: 5 | B9: SAP Technical Consultant | C9: Technical | D9: Offshore | E9: Sr | F9: =SUM('Project Plan'!E62:AO62) -> 0 | G9: =SUM(F9:F9) -> 0
A10: 6 | B10: ABAP / BTP Developer | C10: Technical | D10: Offshore | E10: Jr | F10: =SUM('Project Plan'!E63:AO63) -> 0 | G10: =SUM(F10:F10) -> 0
A11: 7 | B11: Integration Developer (CPI) | C11: Technical | D11: Offshore | E11: Sr | F11: =SUM('Project Plan'!E64:AO64) -> 0 | G11: =SUM(F11:F11) -> 0
A12: 8 | B12: SAP Basis Administrator | C12: Platform | D12: Offshore | E12: Sr | F12: =SUM('Project Plan'!E65:AO65) -> 0 | G12: =SUM(F12:F12) -> 0
A13: 9 | B13: Security Consultant | C13: Technical | D13: Onsite | E13: Sr | F13: =SUM('Project Plan'!E66:AO66) -> 0 | G13: =SUM(F13:F13) -> 0
A14: 10 | B14: Project Manager | C14: Governance | D14: Onsite | E14: PM | F14: =SUM('Project Plan'!E67:AO67) -> 0 | G14: =SUM(F14:F14) -> 0
A15: 11 | B15: Service Delivery Manager | C15: Governance | D15: Onsite | E15: SDM | F15: =SUM('Project Plan'!E68:AO68) -> 0 | G15: =SUM(F15:F15) -> 0
A16: 12 | B16: Change Management Lead | C16: Governance | D16: Onsite | E16: Sr | F16: =SUM('Project Plan'!E69:AO69) -> 0 | G16: =SUM(F16:F16) -> 0
... A19: 15 | B19: AI / Analytics Consultant | C19: AI | D19: Offshore | E19: Sr | F19: =SUM('Project Plan'!E72:AO72) -> 0 | G19: =SUM(F19:F19) -> 0
A20: 16 | F20: =SUM('Project Plan'!E73:AO73) -> 0 | G20: =SUM(F20:F20) -> 0
A21: 17 | F21: =SUM('Project Plan'!E74:AO74) -> 0 | G21: =SUM(F21:F21) -> 0
A22: 18 | F22: =SUM('Project Plan'!E75:AO75) -> 0 | G22: =SUM(F22:F22) -> 0
A23: 19 | F23: =SUM('Project Plan'!E76:AO76) -> 0 | G23: =SUM(F23:F23) -> 0
A24: 20 | F24: =SUM('Project Plan'!E77:AO77) -> 0 | G24: =SUM(F24:F24) -> 0
A25: TOTAL | F25: =SUM(F5:F24) -> 0 | G25: =SUM(G5:G24) -> 0
A27: Summary by Level
A28: Level | B28: Description | C28: 2026 | D28: Total
A29: Jr | B29: Junior | C29: =SUMIF(E5:E24,"Jr",F5:F24) -> 0 | D29: =SUM(C29:C29) -> 0
A30: Sr | B30: Senior | C30: =SUMIF(E5:E24,"Sr",F5:F24) -> 0 | D30: =SUM(C30:C30) -> 0
A31: Sol. Architect | B31: Solution Architect | C31: =SUMIF(E5:E24,"Sol. Architect",F5:F24) -> 0 | D31: =SUM(C31:C31) -> 0
A32: PM | B32: Project Manager | C32: =SUMIF(E5:E24,"PM",F5:F24) -> 0 | D32: =SUM(C32:C32) -> 0
A33: SDM | B33: Service Delivery Manager | C33: =SUMIF(E5:E24,"SDM",F5:F24) -> 0 | D33: =SUM(C33:C33) -> 0
A35: Summary by Description
A36: Category | B36: 2026 | C36: Total
A37: Functional | B37: =SUMIF(C5:C24,"Functional",F5:F24) -> 0 | C37: =SUM(B37:B37) -> 0
A38: Technical | B38: =SUMIF(C5:C24,"Technical",F5:F24) -> 0 | C38: =SUM(B38:B38) -> 0
A39: Governance | B39: =SUMIF(C5:C24,"Governance",F5:F24) -> 0 | C39: =SUM(B39:B39) -> 0
A40: Quality | B40: =SUMIF(C5:C24,"Quality",F5:F24) -> 0 | C40: =SUM(B40:B40) -> 0
A41: Platform | B41: =SUMIF(C5:C24,"Platform",F5:F24) -> 0 | C41: =SUM(B41:B41) -> 0
A42: AI | B42: =SUMIF(C5:C24,"AI",F5:F24) -> 0 | C42: =SUM(B42:B42) -> 0
